<?xml version='1.0' encoding='utf-8'?>
<robot name="iiwa14">
  
  <link name="base_link">
    <visual>
      <origin rpy="0 0 0" xyz="0 0 0" />
      <geometry>
        <mesh filename="../meshes/iiwa14/base_link.dae" />
      </geometry>
    </visual>
  </link>
  <link name="link_1">
    <visual>
      <origin rpy="0 0 0" xyz="0 0 0" />
      <geometry>
        <mesh filename="../meshes/iiwa14/link_1.dae" />
      </geometry>
    </visual>
  </link>
  <link name="link_2">
    <visual>
      <origin rpy="0 0 0" xyz="0 0 0" />
      <geometry>
        <mesh filename="../meshes/iiwa14/link_2.dae" />
      </geometry>
    </visual>
  </link>
  <link name="link_3">
    <visual>
      <origin rpy="0 0 0" xyz="0 0 0" />
      <geometry>
        <mesh filename="../meshes/iiwa14/link_3.dae" />
      </geometry>
    </visual>
  </link>
  <link name="link_4">
    <visual>
      <origin rpy="0 0 0" xyz="0 0 0" />
      <geometry>
        <mesh filename="../meshes/iiwa14/link_4.dae" />
      </geometry>
    </visual>
  </link>
  <link name="link_5">
    <visual>
      <origin rpy="0 0 0" xyz="0 0 0" />
      <geometry>
        <mesh filename="../meshes/iiwa14/link_5.dae" />
      </geometry>
    </visual>
  </link>
  <link name="link_6">
    <visual>
      <origin rpy="0 0 0" xyz="0 0 0" />
      <geometry>
        <mesh filename="../meshes/iiwa14/link_6.dae" />
      </geometry>
    </visual>
  </link>
  <link name="link_7">
    <visual>
      <origin rpy="0 0 0" xyz="0 0 0" />
      <geometry>
        <mesh filename="../meshes/iiwa14/link_7.dae" />
      </geometry>
    </visual>
  </link>
  <link name="tool0" />
  
  
  <joint name="joint_a1" type="revolute">
    <origin rpy="-1.0087381980527947e-17 -1.1201081616714074e-17 9.387736496830478e-18" xyz="9.796829175859443e-18 1.6375378736544188e-17 -1.051918196516921e-17" />
    <parent link="base_link" />
    <child link="link_1" />
    <axis xyz="0 0 1" />
    <limit effort="0" lower="-2.9668" upper="2.9668" velocity="1.4834" />
  </joint>
  <joint name="joint_a2" type="revolute">
    <origin rpy="-0.00023957084824298986 -5.6884041128204696e-05 7.189328531327899e-07" xyz="6.641556196002186e-06 -4.850308280010748e-05 0.36" />
    <parent link="link_1" />
    <child link="link_2" />
    <axis xyz="0 1 0" />
    <limit effort="0" lower="-2.0942" upper="2.0942" velocity="1.4834" />
  </joint>
  <joint name="joint_a3" type="revolute">
    <origin rpy="0.00035247719173224203 -5.641319300361303e-05 -0.00048623854784495777" xyz="-4.1512419260559245e-05 -4.857645628666963e-05 0.0004263020454594156" />
    <parent link="link_2" />
    <child link="link_3" />
    <axis xyz="0 0 1" />
    <limit effort="0" lower="-2.9668" upper="2.9668" velocity="1.7452" />
  </joint>
  <joint name="joint_a4" type="revolute">
    <origin rpy="-0.0002309957004611178 0.0008274779749400593 -0.0004865078711990348" xyz="0.0002035968730163696 -2.4161913843876915e-05 0.4204270744461477" />
    <parent link="link_3" />
    <child link="link_4" />
    <axis xyz="0 -1 0" />
    <limit effort="0" lower="-2.0942" upper="2.0942" velocity="1.3089" />
  </joint>
  <joint name="joint_a5" type="revolute">
    <origin rpy="-0.00031193046405390704 0.0008275922709424341 0.0004960384600336252" xyz="4.649266192632678e-05 -2.4391165706126887e-05 8.987416134611991e-05" />
    <parent link="link_4" />
    <child link="link_5" />
    <axis xyz="0 0 1" />
    <limit effort="0" lower="-2.9668" upper="2.9668" velocity="2.2688" />
  </joint>
  <joint name="joint_a6" type="revolute">
    <origin rpy="-0.0003893062106514123 1.1738287155927405e-05 0.0004964157882689584" xyz="-7.360162660555994e-07 3.0938390954099316e-05 0.4000901941936387" />
    <parent link="link_5" />
    <child link="link_6" />
    <axis xyz="0 1 0" />
    <limit effort="0" lower="-2.0942" upper="2.0942" velocity="2.356" />
  </joint>
  <joint name="joint_a7" type="revolute">
    <origin rpy="6.00942282538721e-06 1.1505438487787744e-05 -3.510203372660091e-09" xyz="2.6752380927295418e-05 3.080351825746838e-05 2.823749825184663e-06" />
    <parent link="link_6" />
    <child link="link_7" />
    <axis xyz="0 0 1" />
    <limit effort="0" lower="-3.0541" upper="3.0541" velocity="2.356" />
  </joint>
  <joint name="joint_a7-tool0" type="fixed">
    <origin rpy="0 0 0" xyz="0 0 0.126" />
    <parent link="link_7" />
    <child link="tool0" />
    <axis xyz="0 0 0" />
  </joint>
  
  
  <link name="base" />
  <joint name="base_link-base" type="fixed">
    <origin rpy="0 0 0" xyz="0 0 0" />
    <parent link="base_link" />
    <child link="base" />
  </joint>
  <link name="ball_link">
    <visual>
      <material name="red">
        <color rgba="1 0 0 1" />
      </material>

      <geometry>
        <sphere radius="0.005" />
      </geometry>
    </visual>
  </link>
  <joint name="ball_joint" type="fixed">
    
    <origin rpy="0.0 0.0 0.0" xyz="-6.882391094876491e-05 -0.00018700750955332607 0.04085835306856537" />
    <parent link="tool0" />
    <child link="ball_link" />
  </joint>
</robot>